Workbook

Sheet Master Sheet
A1: Today is | B1: Video link | C1: =IF( OR( INDIRECT("'" & C$10 & "'!J2") = "???", INDIRECT("'" & C$10 & "'!J2") = "...", ISBLANK(INDIRECT("'" & C$10 & "'!J2")) ), IF( OR( INDIRECT("'" & C$10 & "'!I2") = "???", INDIRECT("'" & C$10 & "'!I2") = "...", ISBLANK(INDIRECT("'" & C$10 & "'!I2")) ), "No vid", INDIRECT("'" & C$10 & "'!I2") ), INDIRECT("'" & C$10 & "'!J2") ) -> No vid | D1: =IF( OR( INDIRECT("'" & D$10 & "'!J2") = "???", INDIRECT("'" & D$10 & "'!J2") = "...", ISBLANK(INDIRECT("'" & D$10 & "'!J2")) ), IF( OR( INDIRECT("'" & D$10 & "'!I2") = "???", INDIRECT("'" & D$10 & "'!I2") = "...", ISBLANK(INDIRECT("'" & D$10 & "'!I2")) ), "No vid", INDIRECT("'" & D$10 & "'!I2") ), INDIRECT("'" & D$10 & "'!J2") ) -> https://youtu.be/AdNAXgiu1kk | E1: =IF( OR( INDIRECT("'" & E$10 & "'!J2") = "???", INDIRECT("'" & E$10 & "'!J2") = "...", ISBLANK(INDIRECT("'" & E$10 & "'!J2")) ), IF( OR( INDIRECT("'" & E$10 & "'!I2") = "???", INDIRECT("'" & E$10 & "'!I2") = "...", ISBLANK(INDIRECT("'" & E$10 & "'!I2")) ), "No vid", INDIRECT("'" & E$10 & "'!I2") ), INDIRECT("'" & E$10 & "'!J2") ) -> https://youtu.be/wRpE-NXbUqQ | F1: =IF( OR( INDIRECT("'" & F$10 & "'!J2") = "???", INDIRECT("'" & F$10 & "'!J2") = "...", ISBLANK(INDIRECT("'" & F$10 & "'!J2")) ), IF( OR( INDIRECT("'" & F$10 & "'!I2") = "???", INDIRECT("'" & F$10 & "'!I2") = "...", ISBLANK(INDIRECT("'" & F$10 & "'!I2")) ), "No vid", INDIRECT("'" & F$10 & "'!I2") ), INDIRECT("'" & F$10 & "'!J2") ) -> https://youtu.be/9XrEJvCS0MY | G1: =IF( OR( INDIRECT("'" & G$10 & "'!J2") = "???", INDIRECT("'" & G$10 & "'!J2") = "...", ISBLANK(INDIRECT("'" & G$10 & "'!J2")) ), IF( OR( INDIRECT("'" & G$10 & "'!I2") = "???", INDIRECT("'" & G$10 & "'!I2") = "...", ISBLANK(INDIRECT("'" & G$10 & "'!I2")) ), "No vid", INDIRECT("'" & G$10 & "'!I2") ), INDIRECT("'" & G$10 & "'!J2") ) -> https://youtu.be/Vgs0Yb5JH6Y | H1: =IF( OR( INDIRECT("'" & H$10 & "'!J2") = "???", INDIRECT("'" & H$10 & "'!J2") = "...", ISBLANK(INDIRECT("'" & H$10 & "'!J2")) ), IF( OR( INDIRECT("'" & H$10 & "'!I2") = "???", INDIRECT("'" & H$10 & "'!I2") = "...", ISBLANK(INDIRECT("'" & H$10 & "'!I2")) ), "No vid", INDIRECT("'" & H$10 & "'!I2") ), INDIRECT("'" & H$10 & "'!J2") ) -> https://youtu.be/BbMYZRThyxo | I1: =IF( OR( INDIRECT("'" & I$10 & "'!J2") = "???", INDIRECT("'" & I$10 & "'!J2") = "...", ISBLANK(INDIRECT("'" & I$10 & "'!J2")) ), IF( OR( INDIRECT("'" & I$10 & "'!I2") = "???", INDIRECT("'" & I$10 & "'!I2") = "...", ISBLANK(INDIRECT("'" & I$10 & "'!I2")) ), "No vid", INDIRECT("'" & I$10 & "'!I2") ), INDIRECT("'" & I$10 & "'!J2") ) -> https://youtu.be/aNzNFn8fQMw | J1: =IF( OR( INDIRECT("'" & J$10 & "'!J2") = "???", INDIRECT("'" & J$10 & "'!J2") = "...", ISBLANK(INDIRECT("'" & J$10 & "'!J2")) ), IF( OR( INDIRECT("'" & J$10 & "'!I2") = "???", INDIRECT("'" & J$10 & "'!I2") = "...", ISBLANK(INDIRECT("'" & J$10 & "'!I2")) ), "No vid", INDIRECT("'" & J$10 & "'!I2") ), INDIRECT("'" & J$10 & "'!J2") ) -> https://youtu.be/X8rsJu13GSA | ... AU1: =IF( OR( INDIRECT("'" & AU$10 & "'!J2") = "???", INDIRECT("'" & AU$10 & "'!J2") = "...", ISBLANK(INDIRECT("'" & AU$10 & "'!J2")) ), IF( OR( INDIRECT("'" & AU$10 & "'!I2") = "???", INDIRECT("'" & AU$10 & "'!I2") = "...", ISBLANK(INDIRECT("'" & AU$10 & "'!I2")) ), "No vid", INDIRECT("'" & AU$10 & "'!I2") ), INDIRECT("'" & AU$10 & "'!J2") ) -> No vid
A2: =TODAY() -> 46198 | B2: Category | C2: 3x3 ao5 | D2: 3x3 ao12 | E2: 3x3 ao50 | F2: 3x3 ao100 | G2: 3x3 x10 | H2: 3x3 x42 | I2: 4x4 single | J2: 4x4 ao5 | K2: 4x4 ao12 | L2: 4x4 ao50 | M2: 4x4 ao100 | N2: 4x4 x10 | O2: 4x4 x42 | P2: 4x4 relay | Q2: 5x5 single | R2: 5x5 ao5 | S2: 5x5 ao12 | T2: 5x5 ao50 | U2: 5x5 ao100 | V2: 5x5 relay | W2: 6x6 single | X2: 6x6 ao5 | Y2: 6x6 ao12 | Z2: 6x6 relay | AA2: 7x7 single | AB2: 7x7 ao5 | AC2: 7x7 ao12 | AD2: 7x7 relay | AE2: 8x8 single | AF2: 8x8 ao5 | AG2: 9x9 single | AH2: 9x9 ao5 | AI2: 10x10 single | AJ2: 10x10 ao5 | AK2: 11x11 single | AL2: 12x12 single | AM2: 13x13 single | AN2: 14x14 single | AO2: 15x15 single | AP2: 16x16 single | AQ2: 17x17 single | AR2: 18x18 single | AS2: 19x19 single | AT2: 20x20 single | AU2: 30x30 single
B3: Time | C3: =INDIRECT("'" & C$10 & "'!C2") -> 0.337 | D3: =INDIRECT("'" & D$10 & "'!C2") -> 0.505 | E3: =INDIRECT("'" & E$10 & "'!C2") -> 0.65 | F3: =INDIRECT("'" & F$10 & "'!C2") -> 0.736 | G3: =INDIRECT("'" & G$10 & "'!C2") -> 9.953 | H3: =INDIRECT("'" & H$10 & "'!C2") -> 49.962 | I3: =INDIRECT("'" & I$10 & "'!C2") -> 0.909 | J3: =INDIRECT("'" & J$10 & "'!C2") -> 1.794 | ... N3: =INDIRECT("'" & N$10 & "'!C2") -> 26.99 | O3: {=INDIRECT("'" & O$10 & "'!K2")} -> 02:16.323 | P3: =INDIRECT("'" & P$10 & "'!C2") -> 2.309 | Q3: =INDIRECT("'" & Q$10 & "'!C2") -> 3.217 | R3: =INDIRECT("'" & R$10 & "'!C2") -> 4.96 | S3: =INDIRECT("'" & S$10 & "'!C2") -> 5.571 | T3: =INDIRECT("'" & T$10 & "'!C2") -> 6.395 | U3: =INDIRECT("'" & U$10 & "'!C2") -> 6.633 | V3: =INDIRECT("'" & V$10 & "'!C2") -> 7.844 | W3: =INDIRECT("'" & W$10 & "'!C2") -> 7.999 | ... AJ3: =INDIRECT("'" & AJ$10 & "'!C2") -> 56.743 | AK3: =INDIRECT("'" & AK$10 & "'!K2") -> 01:12.059 | AL3: =INDIRECT("'" & AL$10 & "'!K2") -> 01:33.449 | AM3: =INDIRECT("'" & AM$10 & "'!K2") -> 02:02.081 | AN3: =INDIRECT("'" & AN$10 & "'!K2") -> 02:31.269 | AO3: =INDIRECT("'" & AO$10 & "'!K2") -> 03:01.516 | AP3: =INDIRECT("'" & AP$10 & "'!K2") -> 03:33.888 | AQ3: =INDIRECT("'" & AQ$10 & "'!K2") -> 04:39.282 | AR3: =INDIRECT("'" & AR$10 & "'!K2") -> 05:15.632 | ... AU3: =INDIRECT("'" & AU$10 & "'!K2") -> 21:35.136
B4: Moves (rounded) | C4: =INDIRECT("'" & C$10 & "'!D2") -> 13.666 | D4: =INDIRECT("'" & D$10 & "'!D2") -> 20.7 | E4: =INDIRECT("'" & E$10 & "'!D2") -> 23.833 | F4: =INDIRECT("'" & F$10 & "'!D2") -> 26.153 | G4: =INDIRECT("'" & G$10 & "'!D2") -> 241 | H4: =INDIRECT("'" & H$10 & "'!D2") -> 1202 | I4: =INDIRECT("'" & I$10 & "'!D2") -> 26 | J4: =INDIRECT("'" & J$10 & "'!D2") -> 58 | ... AU4: =INDIRECT("'" & AU$10 & "'!D2") -> 50184
B5: TPS (rounded) | C5: =INDIRECT("'" & C$10 & "'!E2") -> 41.992 | D5: =INDIRECT("'" & D$10 & "'!E2") -> 40.787 | E5: =INDIRECT("'" & E$10 & "'!E2") -> 37.563 | F5: =INDIRECT("'" & F$10 & "'!E2") -> 37.017 | G5: =INDIRECT("'" & G$10 & "'!E2") -> 24.213 | H5: =INDIRECT("'" & H$10 & "'!E2") -> 24.058 | I5: =INDIRECT("'" & I$10 & "'!E2") -> 28.602 | J5: =INDIRECT("'" & J$10 & "'!E2") -> 30.992 | ... AU5: =INDIRECT("'" & AU$10 & "'!E2") -> 38.748
B6: Style | C6: =INDIRECT("'" & C$10 & "'!G2") -> Fringe | D6: =INDIRECT("'" & D$10 & "'!G2") -> Fringe | E6: =INDIRECT("'" & E$10 & "'!G2") -> Fringe | F6: =INDIRECT("'" & F$10 & "'!G2") -> Fringe | G6: =INDIRECT("'" & G$10 & "'!G2") -> Fringe | H6: =INDIRECT("'" & H$10 & "'!G2") -> Fringe | I6: =INDIRECT("'" & I$10 & "'!G2") -> Fringe | J6: =INDIRECT("'" & J$10 & "'!G2") -> Fringe | ... AU6: =INDIRECT("'" & AU$10 & "'!G2") -> 30x15 - 15x15 - 15x8 - 8x8 - 4x8 Grids
B7: Controls | C7: =INDIRECT("'" & C$10 & "'!F2") -> Tablet | D7: =INDIRECT("'" & D$10 & "'!F2") -> Tablet | E7: =INDIRECT("'" & E$10 & "'!F2") -> Tablet | F7: =INDIRECT("'" & F$10 & "'!F2") -> Tablet | G7: =INDIRECT("'" & G$10 & "'!F2") -> Tablet | H7: =INDIRECT("'" & H$10 & "'!F2") -> Tablet | I7: =INDIRECT("'" & I$10 & "'!F2") -> Tablet | J7: =INDIRECT("'" & J$10 & "'!F2") -> Tablet | ... AU7: =INDIRECT("'" & AU$10 & "'!F2") -> Mouse
A8: Days since WR | B8: WR Holder | C8: =INDIRECT("'" & C$10 & "'!B2") -> vovker | D8: =INDIRECT("'" & D$10 & "'!B2") -> dphdmn | E8: =INDIRECT("'" & E$10 & "'!B2") -> dphdmn | F8: =INDIRECT("'" & F$10 & "'!B2") -> dphdmn | G8: =INDIRECT("'" & G$10 & "'!B2") -> dphdmn | H8: =INDIRECT("'" & H$10 & "'!B2") -> dphdmn | I8: =INDIRECT("'" & I$10 & "'!B2") -> dphdmn | J8: =INDIRECT("'" & J$10 & "'!B2") -> dphdmn | ... AU8: =INDIRECT("'" & AU$10 & "'!B2") -> vovker
A9: =min(C9:AU9) -> 81 | B9: Days since WR | C9: =TODAY() - DATE( RIGHT(INDIRECT("'" & C$10 & "'!A2"), 4), MID(INDIRECT("'" & C$10 & "'!A2"), 4, 2), LEFT(INDIRECT("'" & C$10 & "'!A2"), 2) ) -> 219 | D9: =TODAY() - DATE( RIGHT(INDIRECT("'" & D$10 & "'!A2"), 4), MID(INDIRECT("'" & D$10 & "'!A2"), 4, 2), LEFT(INDIRECT("'" & D$10 & "'!A2"), 2) ) -> 489 | E9: =TODAY() - DATE( RIGHT(INDIRECT("'" & E$10 & "'!A2"), 4), MID(INDIRECT("'" & E$10 & "'!A2"), 4, 2), LEFT(INDIRECT("'" & E$10 & "'!A2"), 2) ) -> 381 | F9: =TODAY() - DATE( RIGHT(INDIRECT("'" & F$10 & "'!A2"), 4), MID(INDIRECT("'" & F$10 & "'!A2"), 4, 2), LEFT(INDIRECT("'" & F$10 & "'!A2"), 2) ) -> 81 | G9: =TODAY() - DATE( RIGHT(INDIRECT("'" & G$10 & "'!A2"), 4), MID(INDIRECT("'" & G$10 & "'!A2"), 4, 2), LEFT(INDIRECT("'" & G$10 & "'!A2"), 2) ) -> 362 | H9: =TODAY() - DATE( RIGHT(INDIRECT("'" & H$10 & "'!A2"), 4), MID(INDIRECT("'" & H$10 & "'!A2"), 4, 2), LEFT(INDIRECT("'" & H$10 & "'!A2"), 2) ) -> 327 | I9: =TODAY() - DATE( RIGHT(INDIRECT("'" & I$10 & "'!A2"), 4), MID(INDIRECT("'" & I$10 & "'!A2"), 4, 2), LEFT(INDIRECT("'" & I$10 & "'!A2"), 2) ) -> 401 | J9: =TODAY() - DATE( RIGHT(INDIRECT("'" & J$10 & "'!A2"), 4), MID(INDIRECT("'" & J$10 & "'!A2"), 4, 2), LEFT(INDIRECT("'" & J$10 & "'!A2"), 2) ) -> 296 | ... AU9: =TODAY() - DATE( RIGHT(INDIRECT("'" & AU$10 & "'!A2"), 4), MID(INDIRECT("'" & AU$10 & "'!A2"), 4, 2), LEFT(INDIRECT("'" & AU$10 & "'!A2"), 2) ) -> 367
A10: Player | B10: WR Counts | C10: 3x3 ao5 | D10: 3x3 ao12 | E10: 3x3 ao50 | F10: 3x3 ao100 | G10: 3x3 x10 | H10: 3x3 x42 | I10: 4x4 single | J10: 4x4 ao5 | K10: 4x4 ao12 | L10: 4x4 ao50 | M10: 4x4 ao100 | N10: 4x4 x10 | O10: 4x4 x42 | P10: 4x4 relay | Q10: 5x5 single | R10: 5x5 ao5 | S10: 5x5 ao12 | T10: 5x5 ao50 | U10: 5x5 ao100 | V10: 5x5 relay | W10: 6x6 single | X10: 6x6 ao5 | Y10: 6x6 ao12 | Z10: 6x6 relay | AA10: 7x7 single | AB10: 7x7 ao5 | AC10: 7x7 ao12 | AD10: 7x7 relay | AE10: 8x8 single | AF10: 8x8 ao5 | AG10: 9x9 single | AH10: 9x9 ao5 | AI10: 10x10 single | AJ10: 10x10 ao5 | AK10: 11x11 single | AL10: 12x12 single | AM10: 13x13 single | AN10: 14x14 single | AO10: 15x15 single | AP10: 16x16 single | AQ10: 17x17 single | AR10: 18x18 single | AS10: 19x19 single | AT10: 20x20 single | AU10: 30x30 single
A11: dphdmn | B11: =Sum(C11:AU11) -> 125 | C11: =SUMPRODUCT( (INDIRECT("'" & C$10 & "'!B2:B" & COUNTA(INDIRECT("'" & C$10 & "'!B:B"))) = $A11) * (INDIRECT("'" & C$10 & "'!B2:B" & COUNTA(INDIRECT("'" & C$10 & "'!B:B"))) <> INDIRECT("'" & C$10 & "'!B1:B" & COUNTA(INDIRECT("'" & C$10 & "'!B:B")) - 1)) ) -> 2 | D11: =SUMPRODUCT( (INDIRECT("'" & D$10 & "'!B2:B" & COUNTA(INDIRECT("'" & D$10 & "'!B:B"))) = $A11) * (INDIRECT("'" & D$10 & "'!B2:B" & COUNTA(INDIRECT("'" & D$10 & "'!B:B"))) <> INDIRECT("'" & D$10 & "'!B1:B" & COUNTA(INDIRECT("'" & D$10 & "'!B:B")) - 1)) ) -> 3 | E11: =SUMPRODUCT( (INDIRECT("'" & E$10 & "'!B2:B" & COUNTA(INDIRECT("'" & E$10 & "'!B:B"))) = $A11) * (INDIRECT("'" & E$10 & "'!B2:B" & COUNTA(INDIRECT("'" & E$10 & "'!B:B"))) <> INDIRECT("'" & E$10 & "'!B1:B" & COUNTA(INDIRECT("'" & E$10 & "'!B:B")) - 1)) ) -> 3 | F11: =SUMPRODUCT( (INDIRECT("'" & F$10 & "'!B2:B" & COUNTA(INDIRECT("'" & F$10 & "'!B:B"))) = $A11) * (INDIRECT("'" & F$10 & "'!B2:B" & COUNTA(INDIRECT("'" & F$10 & "'!B:B"))) <> INDIRECT("'" & F$10 & "'!B1:B" & COUNTA(INDIRECT("'" & F$10 & "'!B:B")) - 1)) ) -> 3 | G11: =SUMPRODUCT( (INDIRECT("'" & G$10 & "'!B2:B" & COUNTA(INDIRECT("'" & G$10 & "'!B:B"))) = $A11) * (INDIRECT("'" & G$10 & "'!B2:B" & COUNTA(INDIRECT("'" & G$10 & "'!B:B"))) <> INDIRECT("'" & G$10 & "'!B1:B" & COUNTA(INDIRECT("'" & G$10 & "'!B:B")) - 1)) ) -> 6 | H11: =SUMPRODUCT( (INDIRECT("'" & H$10 & "'!B2:B" & COUNTA(INDIRECT("'" & H$10 & "'!B:B"))) = $A11) * (INDIRECT("'" & H$10 & "'!B2:B" & COUNTA(INDIRECT("'" & H$10 & "'!B:B"))) <> INDIRECT("'" & H$10 & "'!B1:B" & COUNTA(INDIRECT("'" & H$10 & "'!B:B")) - 1)) ) -> 4 | I11: =SUMPRODUCT( (INDIRECT("'" & I$10 & "'!B2:B" & COUNTA(INDIRECT("'" & I$10 & "'!B:B"))) = $A11) * (INDIRECT("'" & I$10 & "'!B2:B" & COUNTA(INDIRECT("'" & I$10 & "'!B:B"))) <> INDIRECT("'" & I$10 & "'!B1:B" & COUNTA(INDIRECT("'" & I$10 & "'!B:B")) - 1)) ) -> 2 | J11: =SUMPRODUCT( (INDIRECT("'" & J$10 & "'!B2:B" & COUNTA(INDIRECT("'" & J$10 & "'!B:B"))) = $A11) * (INDIRECT("'" & J$10 & "'!B2:B" & COUNTA(INDIRECT("'" & J$10 & "'!B:B"))) <> INDIRECT("'" & J$10 & "'!B1:B" & COUNTA(INDIRECT("'" & J$10 & "'!B:B")) - 1)) ) -> 5 | ... AU11: =SUMPRODUCT( (INDIRECT("'" & AU$10 & "'!B2:B" & COUNTA(INDIRECT("'" & AU$10 & "'!B:B"))) = $A11) * (INDIRECT("'" & AU$10 & "'!B2:B" & COUNTA(INDIRECT("'" & AU$10 & "'!B:B"))) <> INDIRECT("'" & AU$10 & "'!B1:B" & COUNTA(INDIRECT("'" & AU$10 & "'!B:B")) - 1)) ) -> 1
A12: Dawidluna | B12: =Sum(C12:AU12) -> 85 | C12: =SUMPRODUCT( (INDIRECT("'" & C$10 & "'!B2:B" & COUNTA(INDIRECT("'" & C$10 & "'!B:B"))) = $A12) * (INDIRECT("'" & C$10 & "'!B2:B" & COUNTA(INDIRECT("'" & C$10 & "'!B:B"))) <> INDIRECT("'" & C$10 & "'!B1:B" & COUNTA(INDIRECT("'" & C$10 & "'!B:B")) - 1)) ) -> 1 | D12: =SUMPRODUCT( (INDIRECT("'" & D$10 & "'!B2:B" & COUNTA(INDIRECT("'" & D$10 & "'!B:B"))) = $A12) * (INDIRECT("'" & D$10 & "'!B2:B" & COUNTA(INDIRECT("'" & D$10 & "'!B:B"))) <> INDIRECT("'" & D$10 & "'!B1:B" & COUNTA(INDIRECT("'" & D$10 & "'!B:B")) - 1)) ) -> 1 | E12: =SUMPRODUCT( (INDIRECT("'" & E$10 & "'!B2:B" & COUNTA(INDIRECT("'" & E$10 & "'!B:B"))) = $A12) * (INDIRECT("'" & E$10 & "'!B2:B" & COUNTA(INDIRECT("'" & E$10 & "'!B:B"))) <> INDIRECT("'" & E$10 & "'!B1:B" & COUNTA(INDIRECT("'" & E$10 & "'!B:B")) - 1)) ) -> 2 | F12: =SUMPRODUCT( (INDIRECT("'" & F$10 & "'!B2:B" & COUNTA(INDIRECT("'" & F$10 & "'!B:B"))) = $A12) * (INDIRECT("'" & F$10 & "'!B2:B" & COUNTA(INDIRECT("'" & F$10 & "'!B:B"))) <> INDIRECT("'" & F$10 & "'!B1:B" & COUNTA(INDIRECT("'" & F$10 & "'!B:B")) - 1)) ) -> 2 | G12: =SUMPRODUCT( (INDIRECT("'" & G$10 & "'!B2:B" & COUNTA(INDIRECT("'" & G$10 & "'!B:B"))) = $A12) * (INDIRECT("'" & G$10 & "'!B2:B" & COUNTA(INDIRECT("'" & G$10 & "'!B:B"))) <> INDIRECT("'" & G$10 & "'!B1:B" & COUNTA(INDIRECT("'" & G$10 & "'!B:B")) - 1)) ) -> 2 | H12: =SUMPRODUCT( (INDIRECT("'" & H$10 & "'!B2:B" & COUNTA(INDIRECT("'" & H$10 & "'!B:B"))) = $A12) * (INDIRECT("'" & H$10 & "'!B2:B" & COUNTA(INDIRECT("'" & H$10 & "'!B:B"))) <> INDIRECT("'" & H$10 & "'!B1:B" & COUNTA(INDIRECT("'" & H$10 & "'!B:B")) - 1)) ) -> 2 | I12: =SUMPRODUCT( (INDIRECT("'" & I$10 & "'!B2:B" & COUNTA(INDIRECT("'" & I$10 & "'!B:B"))) = $A12) * (INDIRECT("'" & I$10 & "'!B2:B" & COUNTA(INDIRECT("'" & I$10 & "'!B:B"))) <> INDIRECT("'" & I$10 & "'!B1:B" & COUNTA(INDIRECT("'" & I$10 & "'!B:B")) - 1)) ) -> 0 | J12: =SUMPRODUCT( (INDIRECT("'" & J$10 & "'!B2:B" & COUNTA(INDIRECT("'" & J$10 & "'!B:B"))) = $A12) * (INDIRECT("'" & J$10 & "'!B2:B" & COUNTA(INDIRECT("'" & J$10 & "'!B:B"))) <> INDIRECT("'" & J$10 & "'!B1:B" & COUNTA(INDIRECT("'" & J$10 & "'!B:B")) - 1)) ) -> 2 | ... AU12: =SUMPRODUCT( (INDIRECT("'" & AU$10 & "'!B2:B" & COUNTA(INDIRECT("'" & AU$10 & "'!B:B"))) = $A12) * (INDIRECT("'" & AU$10 & "'!B2:B" & COUNTA(INDIRECT("'" & AU$10 & "'!B:B"))) <> INDIRECT("'" & AU$10 & "'!B1:B" & COUNTA(INDIRECT("'" & AU$10 & "'!B:B")) - 1)) ) -> 0
A13: vovker | B13: =Sum(C13:AU13) -> 72 | C13: =SUMPRODUCT( (INDIRECT("'" & C$10 & "'!B2:B" & COUNTA(INDIRECT("'" & C$10 & "'!B:B"))) = $A13) * (INDIRECT("'" & C$10 & "'!B2:B" & COUNTA(INDIRECT("'" & C$10 & "'!B:B"))) <> INDIRECT("'" & C$10 & "'!B1:B" & COUNTA(INDIRECT("'" & C$10 & "'!B:B")) - 1)) ) -> 3 | D13: =SUMPRODUCT( (INDIRECT("'" & D$10 & "'!B2:B" & COUNTA(INDIRECT("'" & D$10 & "'!B:B"))) = $A13) * (INDIRECT("'" & D$10 & "'!B2:B" & COUNTA(INDIRECT("'" & D$10 & "'!B:B"))) <> INDIRECT("'" & D$10 & "'!B1:B" & COUNTA(INDIRECT("'" & D$10 & "'!B:B")) - 1)) ) -> 2 | E13: =SUMPRODUCT( (INDIRECT("'" & E$10 & "'!B2:B" & COUNTA(INDIRECT("'" & E$10 & "'!B:B"))) = $A13) * (INDIRECT("'" & E$10 & "'!B2:B" & COUNTA(INDIRECT("'" & E$10 & "'!B:B"))) <> INDIRECT("'" & E$10 & "'!B1:B" & COUNTA(INDIRECT("'" & E$10 & "'!B:B")) - 1)) ) -> 2 | F13: =SUMPRODUCT( (INDIRECT("'" & F$10 & "'!B2:B" & COUNTA(INDIRECT("'" & F$10 & "'!B:B"))) = $A13) * (INDIRECT("'" & F$10 & "'!B2:B" & COUNTA(INDIRECT("'" & F$10 & "'!B:B"))) <> INDIRECT("'" & F$10 & "'!B1:B" & COUNTA(INDIRECT("'" & F$10 & "'!B:B")) - 1)) ) -> 2 | G13: =SUMPRODUCT( (INDIRECT("'" & G$10 & "'!B2:B" & COUNTA(INDIRECT("'" & G$10 & "'!B:B"))) = $A13) * (INDIRECT("'" & G$10 & "'!B2:B" & COUNTA(INDIRECT("'" & G$10 & "'!B:B"))) <> INDIRECT("'" & G$10 & "'!B1:B" & COUNTA(INDIRECT("'" & G$10 & "'!B:B")) - 1)) ) -> 4 | H13: =SUMPRODUCT( (INDIRECT("'" & H$10 & "'!B2:B" & COUNTA(INDIRECT("'" & H$10 & "'!B:B"))) = $A13) * (INDIRECT("'" & H$10 & "'!B2:B" & COUNTA(INDIRECT("'" & H$10 & "'!B:B"))) <> INDIRECT("'" & H$10 & "'!B1:B" & COUNTA(INDIRECT("'" & H$10 & "'!B:B")) - 1)) ) -> 1 | I13: =SUMPRODUCT( (INDIRECT("'" & I$10 & "'!B2:B" & COUNTA(INDIRECT("'" & I$10 & "'!B:B"))) = $A13) * (INDIRECT("'" & I$10 & "'!B2:B" & COUNTA(INDIRECT("'" & I$10 & "'!B:B"))) <> INDIRECT("'" & I$10 & "'!B1:B" & COUNTA(INDIRECT("'" & I$10 & "'!B:B")) - 1)) ) -> 1 | J13: =SUMPRODUCT( (INDIRECT("'" & J$10 & "'!B2:B" & COUNTA(INDIRECT("'" & J$10 & "'!B:B"))) = $A13) * (INDIRECT("'" & J$10 & "'!B2:B" & COUNTA(INDIRECT("'" & J$10 & "'!B:B"))) <> INDIRECT("'" & J$10 & "'!B1:B" & COUNTA(INDIRECT("'" & J$10 & "'!B:B")) - 1)) ) -> 3 | ... AU13: =SUMPRODUCT( (INDIRECT("'" & AU$10 & "'!B2:B" & COUNTA(INDIRECT("'" & AU$10 & "'!B:B"))) = $A13) * (INDIRECT("'" & AU$10 & "'!B2:B" & COUNTA(INDIRECT("'" & AU$10 & "'!B:B"))) <> INDIRECT("'" & AU$10 & "'!B1:B" & COUNTA(INDIRECT("'" & AU$10 & "'!B:B")) - 1)) ) -> 1
A14: ben1996123 | B14: =Sum(C14:AU14) -> 54 | C14: =SUMPRODUCT( (INDIRECT("'" & C$10 & "'!B2:B" & COUNTA(INDIRECT("'" & C$10 & "'!B:B"))) = $A14) * (INDIRECT("'" & C$10 & "'!B2:B" & COUNTA(INDIRECT("'" & C$10 & "'!B:B"))) <> INDIRECT("'" & C$10 & "'!B1:B" & COUNTA(INDIRECT("'" & C$10 & "'!B:B")) - 1)) ) -> 1 | D14: =SUMPRODUCT( (INDIRECT("'" & D$10 & "'!B2:B" & COUNTA(INDIRECT("'" & D$10 & "'!B:B"))) = $A14) * (INDIRECT("'" & D$10 & "'!B2:B" & COUNTA(INDIRECT("'" & D$10 & "'!B:B"))) <> INDIRECT("'" & D$10 & "'!B1:B" & COUNTA(INDIRECT("'" & D$10 & "'!B:B")) - 1)) ) -> 1 | E14: =SUMPRODUCT( (INDIRECT("'" & E$10 & "'!B2:B" & COUNTA(INDIRECT("'" & E$10 & "'!B:B"))) = $A14) * (INDIRECT("'" & E$10 & "'!B2:B" & COUNTA(INDIRECT("'" & E$10 & "'!B:B"))) <> INDIRECT("'" & E$10 & "'!B1:B" & COUNTA(INDIRECT("'" & E$10 & "'!B:B")) - 1)) ) -> 1 | F14: =SUMPRODUCT( (INDIRECT("'" & F$10 & "'!B2:B" & COUNTA(INDIRECT("'" & F$10 & "'!B:B"))) = $A14) * (INDIRECT("'" & F$10 & "'!B2:B" & COUNTA(INDIRECT("'" & F$10 & "'!B:B"))) <> INDIRECT("'" & F$10 & "'!B1:B" & COUNTA(INDIRECT("'" & F$10 & "'!B:B")) - 1)) ) -> 1 | G14: =SUMPRODUCT( (INDIRECT("'" & G$10 & "'!B2:B" & COUNTA(INDIRECT("'" & G$10 & "'!B:B"))) = $A14) * (INDIRECT("'" & G$10 & "'!B2:B" & COUNTA(INDIRECT("'" & G$10 & "'!B:B"))) <> INDIRECT("'" & G$10 & "'!B1:B" & COUNTA(INDIRECT("'" & G$10 & "'!B:B")) - 1)) ) -> 1 | H14: =SUMPRODUCT( (INDIRECT("'" & H$10 & "'!B2:B" & COUNTA(INDIRECT("'" & H$10 & "'!B:B"))) = $A14) * (INDIRECT("'" & H$10 & "'!B2:B" & COUNTA(INDIRECT("'" & H$10 & "'!B:B"))) <> INDIRECT("'" & H$10 & "'!B1:B" & COUNTA(INDIRECT("'" & H$10 & "'!B:B")) - 1)) ) -> 1 | I14: =SUMPRODUCT( (INDIRECT("'" & I$10 & "'!B2:B" & COUNTA(INDIRECT("'" & I$10 & "'!B:B"))) = $A14) * (INDIRECT("'" & I$10 & "'!B2:B" & COUNTA(INDIRECT("'" & I$10 & "'!B:B"))) <> INDIRECT("'" & I$10 & "'!B1:B" & COUNTA(INDIRECT("'" & I$10 & "'!B:B")) - 1)) ) -> 2 | J14: =SUMPRODUCT( (INDIRECT("'" & J$10 & "'!B2:B" & COUNTA(INDIRECT("'" & J$10 & "'!B:B"))) = $A14) * (INDIRECT("'" & J$10 & "'!B2:B" & COUNTA(INDIRECT("'" & J$10 & "'!B:B"))) <> INDIRECT("'" & J$10 & "'!B1:B" & COUNTA(INDIRECT("'" & J$10 & "'!B:B")) - 1)) ) -> 1 | ... AU14: =SUMPRODUCT( (INDIRECT("'" & AU$10 & "'!B2:B" & COUNTA(INDIRECT("'" & AU$10 & "'!B:B"))) = $A14) * (INDIRECT("'" & AU$10 & "'!B2:B" & COUNTA(INDIRECT("'" & AU$10 & "'!B:B"))) <> INDIRECT("'" & AU$10 & "'!B1:B" & COUNTA(INDIRECT("'" & AU$10 & "'!B:B")) - 1)) ) -> 2
A15: soup | B15: =Sum(C15:AU15) -> 32 | C15: =SUMPRODUCT( (INDIRECT("'" & C$10 & "'!B2:B" & COUNTA(INDIRECT("'" & C$10 & "'!B:B"))) = $A15) * (INDIRECT("'" & C$10 & "'!B2:B" & COUNTA(INDIRECT("'" & C$10 & "'!B:B"))) <> INDIRECT("'" & C$10 & "'!B1:B" & COUNTA(INDIRECT("'" & C$10 & "'!B:B")) - 1)) ) -> 0 | D15: =SUMPRODUCT( (INDIRECT("'" & D$10 & "'!B2:B" & COUNTA(INDIRECT("'" & D$10 & "'!B:B"))) = $A15) * (INDIRECT("'" & D$10 & "'!B2:B" & COUNTA(INDIRECT("'" & D$10 & "'!B:B"))) <> INDIRECT("'" & D$10 & "'!B1:B" & COUNTA(INDIRECT("'" & D$10 & "'!B:B")) - 1)) ) -> 0 | E15: =SUMPRODUCT( (INDIRECT("'" & E$10 & "'!B2:B" & COUNTA(INDIRECT("'" & E$10 & "'!B:B"))) = $A15) * (INDIRECT("'" & E$10 & "'!B2:B" & COUNTA(INDIRECT("'" & E$10 & "'!B:B"))) <> INDIRECT("'" & E$10 & "'!B1:B" & COUNTA(INDIRECT("'" & E$10 & "'!B:B")) - 1)) ) -> 0 | F15: =SUMPRODUCT( (INDIRECT("'" & F$10 & "'!B2:B" & COUNTA(INDIRECT("'" & F$10 & "'!B:B"))) = $A15) * (INDIRECT("'" & F$10 & "'!B2:B" & COUNTA(INDIRECT("'" & F$10 & "'!B:B"))) <> INDIRECT("'" & F$10 & "'!B1:B" & COUNTA(INDIRECT("'" & F$10 & "'!B:B")) - 1)) ) -> 0 | G15: =SUMPRODUCT( (INDIRECT("'" & G$10 & "'!B2:B" & COUNTA(INDIRECT("'" & G$10 & "'!B:B"))) = $A15) * (INDIRECT("'" & G$10 & "'!B2:B" & COUNTA(INDIRECT("'" & G$10 & "'!B:B"))) <> INDIRECT("'" & G$10 & "'!B1:B" & COUNTA(INDIRECT("'" & G$10 & "'!B:B")) - 1)) ) -> 1 | H15: =SUMPRODUCT( (INDIRECT("'" & H$10 & "'!B2:B" & COUNTA(INDIRECT("'" & H$10 & "'!B:B"))) = $A15) * (INDIRECT("'" & H$10 & "'!B2:B" & COUNTA(INDIRECT("'" & H$10 & "'!B:B"))) <> INDIRECT("'" & H$10 & "'!B1:B" & COUNTA(INDIRECT("'" & H$10 & "'!B:B")) - 1)) ) -> 0 | I15: =SUMPRODUCT( (INDIRECT("'" & I$10 & "'!B2:B" & COUNTA(INDIRECT("'" & I$10 & "'!B:B"))) = $A15) * (INDIRECT("'" & I$10 & "'!B2:B" & COUNTA(INDIRECT("'" & I$10 & "'!B:B"))) <> INDIRECT("'" & I$10 & "'!B1:B" & COUNTA(INDIRECT("'" & I$10 & "'!B:B")) - 1)) ) -> 0 | J15: =SUMPRODUCT( (INDIRECT("'" & J$10 & "'!B2:B" & COUNTA(INDIRECT("'" & J$10 & "'!B:B"))) = $A15) * (INDIRECT("'" & J$10 & "'!B2:B" & COUNTA(INDIRECT("'" & J$10 & "'!B:B"))) <> INDIRECT("'" & J$10 & "'!B1:B" & COUNTA(INDIRECT("'" & J$10 & "'!B:B")) - 1)) ) -> 0 | ... AU15: =SUMPRODUCT( (INDIRECT("'" & AU$10 & "'!B2:B" & COUNTA(INDIRECT("'" & AU$10 & "'!B:B"))) = $A15) * (INDIRECT("'" & AU$10 & "'!B2:B" & COUNTA(INDIRECT("'" & AU$10 & "'!B:B"))) <> INDIRECT("'" & AU$10 & "'!B1:B" & COUNTA(INDIRECT("'" & AU$10 & "'!B:B")) - 1)) ) -> 0
A16: Daanbe | B16: =Sum(C16:AU16) -> 27 | C16: =SUMPRODUCT( (INDIRECT("'" & C$10 & "'!B2:B" & COUNTA(INDIRECT("'" & C$10 & "'!B:B"))) = $A16) * (INDIRECT("'" & C$10 & "'!B2:B" & COUNTA(INDIRECT("'" & C$10 & "'!B:B"))) <> INDIRECT("'" & C$10 & "'!B1:B" & COUNTA(INDIRECT("'" & C$10 & "'!B:B")) - 1)) ) -> 0 | D16: =SUMPRODUCT( (INDIRECT("'" & D$10 & "'!B2:B" & COUNTA(INDIRECT("'" & D$10 & "'!B:B"))) = $A16) * (INDIRECT("'" & D$10 & "'!B2:B" & COUNTA(INDIRECT("'" & D$10 & "'!B:B"))) <> INDIRECT("'" & D$10 & "'!B1:B" & COUNTA(INDIRECT("'" & D$10 & "'!B:B")) - 1)) ) -> 0 | E16: =SUMPRODUCT( (INDIRECT("'" & E$10 & "'!B2:B" & COUNTA(INDIRECT("'" & E$10 & "'!B:B"))) = $A16) * (INDIRECT("'" & E$10 & "'!B2:B" & COUNTA(INDIRECT("'" & E$10 & "'!B:B"))) <> INDIRECT("'" & E$10 & "'!B1:B" & COUNTA(INDIRECT("'" & E$10 & "'!B:B")) - 1)) ) -> 0 | F16: =SUMPRODUCT( (INDIRECT("'" & F$10 & "'!B2:B" & COUNTA(INDIRECT("'" & F$10 & "'!B:B"))) = $A16) * (INDIRECT("'" & F$10 & "'!B2:B" & COUNTA(INDIRECT("'" & F$10 & "'!B:B"))) <> INDIRECT("'" & F$10 & "'!B1:B" & COUNTA(INDIRECT("'" & F$10 & "'!B:B")) - 1)) ) -> 0 | G16: =SUMPRODUCT( (INDIRECT("'" & G$10 & "'!B2:B" & COUNTA(INDIRECT("'" & G$10 & "'!B:B"))) = $A16) * (INDIRECT("'" & G$10 & "'!B2:B" & COUNTA(INDIRECT("'" & G$10 & "'!B:B"))) <> INDIRECT("'" & G$10 & "'!B1:B" & COUNTA(INDIRECT("'" & G$10 & "'!B:B")) - 1)) ) -> 0 | H16: =SUMPRODUCT( (INDIRECT("'" & H$10 & "'!B2:B" & COUNTA(INDIRECT("'" & H$10 & "'!B:B"))) = $A16) * (INDIRECT("'" & H$10 & "'!B2:B" & COUNTA(INDIRECT("'" & H$10 & "'!B:B"))) <> INDIRECT("'" & H$10 & "'!B1:B" & COUNTA(INDIRECT("'" & H$10 & "'!B:B")) - 1)) ) -> 0 | I16: =SUMPRODUCT( (INDIRECT("'" & I$10 & "'!B2:B" & COUNTA(INDIRECT("'" & I$10 & "'!B:B"))) = $A16) * (INDIRECT("'" & I$10 & "'!B2:B" & COUNTA(INDIRECT("'" & I$10 & "'!B:B"))) <> INDIRECT("'" & I$10 & "'!B1:B" & COUNTA(INDIRECT("'" & I$10 & "'!B:B")) - 1)) ) -> 0 | J16: =SUMPRODUCT( (INDIRECT("'" & J$10 & "'!B2:B" & COUNTA(INDIRECT("'" & J$10 & "'!B:B"))) = $A16) * (INDIRECT("'" & J$10 & "'!B2:B" & COUNTA(INDIRECT("'" & J$10 & "'!B:B"))) <> INDIRECT("'" & J$10 & "'!B1:B" & COUNTA(INDIRECT("'" & J$10 & "'!B:B")) - 1)) ) -> 0 | ... AU16: =SUMPRODUCT( (INDIRECT("'" & AU$10 & "'!B2:B" & COUNTA(INDIRECT("'" & AU$10 & "'!B:B"))) = $A16) * (INDIRECT("'" & AU$10 & "'!B2:B" & COUNTA(INDIRECT("'" & AU$10 & "'!B:B"))) <> INDIRECT("'" & AU$10 & "'!B1:B" & COUNTA(INDIRECT("'" & AU$10 & "'!B:B")) - 1)) ) -> 1
A17: JZE | B17: =Sum(C17:AU17) -> 20 | C17: =SUMPRODUCT( (INDIRECT("'" & C$10 & "'!B2:B" & COUNTA(INDIRECT("'" & C$10 & "'!B:B"))) = $A17) * (INDIRECT("'" & C$10 & "'!B2:B" & COUNTA(INDIRECT("'" & C$10 & "'!B:B"))) <> INDIRECT("'" & C$10 & "'!B1:B" & COUNTA(INDIRECT("'" & C$10 & "'!B:B")) - 1)) ) -> 0 | D17: =SUMPRODUCT( (INDIRECT("'" & D$10 & "'!B2:B" & COUNTA(INDIRECT("'" & D$10 & "'!B:B"))) = $A17) * (INDIRECT("'" & D$10 & "'!B2:B" & COUNTA(INDIRECT("'" & D$10 & "'!B:B"))) <> INDIRECT("'" & D$10 & "'!B1:B" & COUNTA(INDIRECT("'" & D$10 & "'!B:B")) - 1)) ) -> 0 | E17: =SUMPRODUCT( (INDIRECT("'" & E$10 & "'!B2:B" & COUNTA(INDIRECT("'" & E$10 & "'!B:B"))) = $A17) * (INDIRECT("'" & E$10 & "'!B2:B" & COUNTA(INDIRECT("'" & E$10 & "'!B:B"))) <> INDIRECT("'" & E$10 & "'!B1:B" & COUNTA(INDIRECT("'" & E$10 & "'!B:B")) - 1)) ) -> 0 | F17: =SUMPRODUCT( (INDIRECT("'" & F$10 & "'!B2:B" & COUNTA(INDIRECT("'" & F$10 & "'!B:B"))) = $A17) * (INDIRECT("'" & F$10 & "'!B2:B" & COUNTA(INDIRECT("'" & F$10 & "'!B:B"))) <> INDIRECT("'" & F$10 & "'!B1:B" & COUNTA(INDIRECT("'" & F$10 & "'!B:B")) - 1)) ) -> 0 | G17: =SUMPRODUCT( (INDIRECT("'" & G$10 & "'!B2:B" & COUNTA(INDIRECT("'" & G$10 & "'!B:B"))) = $A17) * (INDIRECT("'" & G$10 & "'!B2:B" & COUNTA(INDIRECT("'" & G$10 & "'!B:B"))) <> INDIRECT("'" & G$10 & "'!B1:B" & COUNTA(INDIRECT("'" & G$10 & "'!B:B")) - 1)) ) -> 0 | H17: =SUMPRODUCT( (INDIRECT("'" & H$10 & "'!B2:B" & COUNTA(INDIRECT("'" & H$10 & "'!B:B"))) = $A17) * (INDIRECT("'" & H$10 & "'!B2:B" & COUNTA(INDIRECT("'" & H$10 & "'!B:B"))) <> INDIRECT("'" & H$10 & "'!B1:B" & COUNTA(INDIRECT("'" & H$10 & "'!B:B")) - 1)) ) -> 1 | I17: =SUMPRODUCT( (INDIRECT("'" & I$10 & "'!B2:B" & COUNTA(INDIRECT("'" & I$10 & "'!B:B"))) = $A17) * (INDIRECT("'" & I$10 & "'!B2:B" & COUNTA(INDIRECT("'" & I$10 & "'!B:B"))) <> INDIRECT("'" & I$10 & "'!B1:B" & COUNTA(INDIRECT("'" & I$10 & "'!B:B")) - 1)) ) -> 0 | J17: =SUMPRODUCT( (INDIRECT("'" & J$10 & "'!B2:B" & COUNTA(INDIRECT("'" & J$10 & "'!B:B"))) = $A17) * (INDIRECT("'" & J$10 & "'!B2:B" & COUNTA(INDIRECT("'" & J$10 & "'!B:B"))) <> INDIRECT("'" & J$10 & "'!B1:B" & COUNTA(INDIRECT("'" & J$10 & "'!B:B")) - 1)) ) -> 0 | ... AU17: =SUMPRODUCT( (INDIRECT("'" & AU$10 & "'!B2:B" & COUNTA(INDIRECT("'" & AU$10 & "'!B:B"))) = $A17) * (INDIRECT("'" & AU$10 & "'!B2:B" & COUNTA(INDIRECT("'" & AU$10 & "'!B:B"))) <> INDIRECT("'" & AU$10 & "'!B1:B" & COUNTA(INDIRECT("'" & AU$10 & "'!B:B")) - 1)) ) -> 0
A18: gottagitgud | B18: =Sum(C18:AU18) -> 7 | C18: =SUMPRODUCT( (INDIRECT("'" & C$10 & "'!B2:B" & COUNTA(INDIRECT("'" & C$10 & "'!B:B"))) = $A18) * (INDIRECT("'" & C$10 & "'!B2:B" & COUNTA(INDIRECT("'" & C$10 & "'!B:B"))) <> INDIRECT("'" & C$10 & "'!B1:B" & COUNTA(INDIRECT("'" & C$10 & "'!B:B")) - 1)) ) -> 1 | D18: =SUMPRODUCT( (INDIRECT("'" & D$10 & "'!B2:B" & COUNTA(INDIRECT("'" & D$10 & "'!B:B"))) = $A18) * (INDIRECT("'" & D$10 & "'!B2:B" & COUNTA(INDIRECT("'" & D$10 & "'!B:B"))) <> INDIRECT("'" & D$10 & "'!B1:B" & COUNTA(INDIRECT("'" & D$10 & "'!B:B")) - 1)) ) -> 1 | E18: =SUMPRODUCT( (INDIRECT("'" & E$10 & "'!B2:B" & COUNTA(INDIRECT("'" & E$10 & "'!B:B"))) = $A18) * (INDIRECT("'" & E$10 & "'!B2:B" & COUNTA(INDIRECT("'" & E$10 & "'!B:B"))) <> INDIRECT("'" & E$10 & "'!B1:B" & COUNTA(INDIRECT("'" & E$10 & "'!B:B")) - 1)) ) -> 1 | F18: =SUMPRODUCT( (INDIRECT("'" & F$10 & "'!B2:B" & COUNTA(INDIRECT("'" & F$10 & "'!B:B"))) = $A18) * (INDIRECT("'" & F$10 & "'!B2:B" & COUNTA(INDIRECT("'" & F$10 & "'!B:B"))) <> INDIRECT("'" & F$10 & "'!B1:B" & COUNTA(INDIRECT("'" & F$10 & "'!B:B")) - 1)) ) -> 1 | G18: =SUMPRODUCT( (INDIRECT("'" & G$10 & "'!B2:B" & COUNTA(INDIRECT("'" & G$10 & "'!B:B"))) = $A18) * (INDIRECT("'" & G$10 & "'!B2:B" & COUNTA(INDIRECT("'" & G$10 & "'!B:B"))) <> INDIRECT("'" & G$10 & "'!B1:B" & COUNTA(INDIRECT("'" & G$10 & "'!B:B")) - 1)) ) -> 1 | H18: =SUMPRODUCT( (INDIRECT("'" & H$10 & "'!B2:B" & COUNTA(INDIRECT("'" & H$10 & "'!B:B"))) = $A18) * (INDIRECT("'" & H$10 & "'!B2:B" & COUNTA(INDIRECT("'" & H$10 & "'!B:B"))) <> INDIRECT("'" & H$10 & "'!B1:B" & COUNTA(INDIRECT("'" & H$10 & "'!B:B")) - 1)) ) -> 0 | I18: =SUMPRODUCT( (INDIRECT("'" & I$10 & "'!B2:B" & COUNTA(INDIRECT("'" & I$10 & "'!B:B"))) = $A18) * (INDIRECT("'" & I$10 & "'!B2:B" & COUNTA(INDIRECT("'" & I$10 & "'!B:B"))) <> INDIRECT("'" & I$10 & "'!B1:B" & COUNTA(INDIRECT("'" & I$10 & "'!B:B")) - 1)) ) -> 0 | J18: =SUMPRODUCT( (INDIRECT("'" & J$10 & "'!B2:B" & COUNTA(INDIRECT("'" & J$10 & "'!B:B"))) = $A18) * (INDIRECT("'" & J$10 & "'!B2:B" & COUNTA(INDIRECT("'" & J$10 & "'!B:B"))) <> INDIRECT("'" & J$10 & "'!B1:B" & COUNTA(INDIRECT("'" & J$10 & "'!B:B")) - 1)) ) -> 0 | ... AU18: =SUMPRODUCT( (INDIRECT("'" & AU$10 & "'!B2:B" & COUNTA(INDIRECT("'" & AU$10 & "'!B:B"))) = $A18) * (INDIRECT("'" & AU$10 & "'!B2:B" & COUNTA(INDIRECT("'" & AU$10 & "'!B:B"))) <> INDIRECT("'" & AU$10 & "'!B1:B" & COUNTA(INDIRECT("'" & AU$10 & "'!B:B")) - 1)) ) -> 0
A19: qqwref | B19: =Sum(C19:AU19) -> 6 | C19: =SUMPRODUCT( (INDIRECT("'" & C$10 & "'!B2:B" & COUNTA(INDIRECT("'" & C$10 & "'!B:B"))) = $A19) * (INDIRECT("'" & C$10 & "'!B2:B" & COUNTA(INDIRECT("'" & C$10 & "'!B:B"))) <> INDIRECT("'" & C$10 & "'!B1:B" & COUNTA(INDIRECT("'" & C$10 & "'!B:B")) - 1)) ) -> 0 | D19: =SUMPRODUCT( (INDIRECT("'" & D$10 & "'!B2:B" & COUNTA(INDIRECT("'" & D$10 & "'!B:B"))) = $A19) * (INDIRECT("'" & D$10 & "'!B2:B" & COUNTA(INDIRECT("'" & D$10 & "'!B:B"))) <> INDIRECT("'" & D$10 & "'!B1:B" & COUNTA(INDIRECT("'" & D$10 & "'!B:B")) - 1)) ) -> 0 | E19: =SUMPRODUCT( (INDIRECT("'" & E$10 & "'!B2:B" & COUNTA(INDIRECT("'" & E$10 & "'!B:B"))) = $A19) * (INDIRECT("'" & E$10 & "'!B2:B" & COUNTA(INDIRECT("'" & E$10 & "'!B:B"))) <> INDIRECT("'" & E$10 & "'!B1:B" & COUNTA(INDIRECT("'" & E$10 & "'!B:B")) - 1)) ) -> 0 | F19: =SUMPRODUCT( (INDIRECT("'" & F$10 & "'!B2:B" & COUNTA(INDIRECT("'" & F$10 & "'!B:B"))) = $A19) * (INDIRECT("'" & F$10 & "'!B2:B" & COUNTA(INDIRECT("'" & F$10 & "'!B:B"))) <> INDIRECT("'" & F$10 & "'!B1:B" & COUNTA(INDIRECT("'" & F$10 & "'!B:B")) - 1)) ) -> 0 | G19: =SUMPRODUCT( (INDIRECT("'" & G$10 & "'!B2:B" & COUNTA(INDIRECT("'" & G$10 & "'!B:B"))) = $A19) * (INDIRECT("'" & G$10 & "'!B2:B" & COUNTA(INDIRECT("'" & G$10 & "'!B:B"))) <> INDIRECT("'" & G$10 & "'!B1:B" & COUNTA(INDIRECT("'" & G$10 & "'!B:B")) - 1)) ) -> 0 | H19: =SUMPRODUCT( (INDIRECT("'" & H$10 & "'!B2:B" & COUNTA(INDIRECT("'" & H$10 & "'!B:B"))) = $A19) * (INDIRECT("'" & H$10 & "'!B2:B" & COUNTA(INDIRECT("'" & H$10 & "'!B:B"))) <> INDIRECT("'" & H$10 & "'!B1:B" & COUNTA(INDIRECT("'" & H$10 & "'!B:B")) - 1)) ) -> 0 | I19: =SUMPRODUCT( (INDIRECT("'" & I$10 & "'!B2:B" & COUNTA(INDIRECT("'" & I$10 & "'!B:B"))) = $A19) * (INDIRECT("'" & I$10 & "'!B2:B" & COUNTA(INDIRECT("'" & I$10 & "'!B:B"))) <> INDIRECT("'" & I$10 & "'!B1:B" & COUNTA(INDIRECT("'" & I$10 & "'!B:B")) - 1)) ) -> 0 | J19: =SUMPRODUCT( (INDIRECT("'" & J$10 & "'!B2:B" & COUNTA(INDIRECT("'" & J$10 & "'!B:B"))) = $A19) * (INDIRECT("'" & J$10 & "'!B2:B" & COUNTA(INDIRECT("'" & J$10 & "'!B:B"))) <> INDIRECT("'" & J$10 & "'!B1:B" & COUNTA(INDIRECT("'" & J$10 & "'!B:B")) - 1)) ) -> 0 | ... AU19: =SUMPRODUCT( (INDIRECT("'" & AU$10 & "'!B2:B" & COUNTA(INDIRECT("'" & AU$10 & "'!B:B"))) = $A19) * (INDIRECT("'" & AU$10 & "'!B2:B" & COUNTA(INDIRECT("'" & AU$10 & "'!B:B"))) <> INDIRECT("'" & AU$10 & "'!B1:B" & COUNTA(INDIRECT("'" & AU$10 & "'!B:B")) - 1)) ) -> 0
A20: tnum10 | B20: =Sum(C20:AU20) -> 3 | C20: =SUMPRODUCT( (INDIRECT("'" & C$10 & "'!B2:B" & COUNTA(INDIRECT("'" & C$10 & "'!B:B"))) = $A20) * (INDIRECT("'" & C$10 & "'!B2:B" & COUNTA(INDIRECT("'" & C$10 & "'!B:B"))) <> INDIRECT("'" & C$10 & "'!B1:B" & COUNTA(INDIRECT("'" & C$10 & "'!B:B")) - 1)) ) -> 0 | D20: =SUMPRODUCT( (INDIRECT("'" & D$10 & "'!B2:B" & COUNTA(INDIRECT("'" & D$10 & "'!B:B"))) = $A20) * (INDIRECT("'" & D$10 & "'!B2:B" & COUNTA(INDIRECT("'" & D$10 & "'!B:B"))) <> INDIRECT("'" & D$10 & "'!B1:B" & COUNTA(INDIRECT("'" & D$10 & "'!B:B")) - 1)) ) -> 0 | E20: =SUMPRODUCT( (INDIRECT("'" & E$10 & "'!B2:B" & COUNTA(INDIRECT("'" & E$10 & "'!B:B"))) = $A20) * (INDIRECT("'" & E$10 & "'!B2:B" & COUNTA(INDIRECT("'" & E$10 & "'!B:B"))) <> INDIRECT("'" & E$10 & "'!B1:B" & COUNTA(INDIRECT("'" & E$10 & "'!B:B")) - 1)) ) -> 0 | F20: =SUMPRODUCT( (INDIRECT("'" & F$10 & "'!B2:B" & COUNTA(INDIRECT("'" & F$10 & "'!B:B"))) = $A20) * (INDIRECT("'" & F$10 & "'!B2:B" & COUNTA(INDIRECT("'" & F$10 & "'!B:B"))) <> INDIRECT("'" & F$10 & "'!B1:B" & COUNTA(INDIRECT("'" & F$10 & "'!B:B")) - 1)) ) -> 0 | G20: =SUMPRODUCT( (INDIRECT("'" & G$10 & "'!B2:B" & COUNTA(INDIRECT("'" & G$10 & "'!B:B"))) = $A20) * (INDIRECT("'" & G$10 & "'!B2:B" & COUNTA(INDIRECT("'" & G$10 & "'!B:B"))) <> INDIRECT("'" & G$10 & "'!B1:B" & COUNTA(INDIRECT("'" & G$10 & "'!B:B")) - 1)) ) -> 0 | H20: =SUMPRODUCT( (INDIRECT("'" & H$10 & "'!B2:B" & COUNTA(INDIRECT("'" & H$10 & "'!B:B"))) = $A20) * (INDIRECT("'" & H$10 & "'!B2:B" & COUNTA(INDIRECT("'" & H$10 & "'!B:B"))) <> INDIRECT("'" & H$10 & "'!B1:B" & COUNTA(INDIRECT("'" & H$10 & "'!B:B")) - 1)) ) -> 0 | I20: =SUMPRODUCT( (INDIRECT("'" & I$10 & "'!B2:B" & COUNTA(INDIRECT("'" & I$10 & "'!B:B"))) = $A20) * (INDIRECT("'" & I$10 & "'!B2:B" & COUNTA(INDIRECT("'" & I$10 & "'!B:B"))) <> INDIRECT("'" & I$10 & "'!B1:B" & COUNTA(INDIRECT("'" & I$10 & "'!B:B")) - 1)) ) -> 0 | J20: =SUMPRODUCT( (INDIRECT("'" & J$10 & "'!B2:B" & COUNTA(INDIRECT("'" & J$10 & "'!B:B"))) = $A20) * (INDIRECT("'" & J$10 & "'!B2:B" & COUNTA(INDIRECT("'" & J$10 & "'!B:B"))) <> INDIRECT("'" & J$10 & "'!B1:B" & COUNTA(INDIRECT("'" & J$10 & "'!B:B")) - 1)) ) -> 0 | ... AU20: =SUMPRODUCT( (INDIRECT("'" & AU$10 & "'!B2:B" & COUNTA(INDIRECT("'" & AU$10 & "'!B:B"))) = $A20) * (INDIRECT("'" & AU$10 & "'!B2:B" & COUNTA(INDIRECT("'" & AU$10 & "'!B:B"))) <> INDIRECT("'" & AU$10 & "'!B1:B" & COUNTA(INDIRECT("'" & AU$10 & "'!B:B")) - 1)) ) -> 0
A21: eff | B21: =Sum(C21:AU21) -> 2 | C21: =SUMPRODUCT( (INDIRECT("'" & C$10 & "'!B2:B" & COUNTA(INDIRECT("'" & C$10 & "'!B:B"))) = $A21) * (INDIRECT("'" & C$10 & "'!B2:B" & COUNTA(INDIRECT("'" & C$10 & "'!B:B"))) <> INDIRECT("'" & C$10 & "'!B1:B" & COUNTA(INDIRECT("'" & C$10 & "'!B:B")) - 1)) ) -> 0 | D21: =SUMPRODUCT( (INDIRECT("'" & D$10 & "'!B2:B" & COUNTA(INDIRECT("'" & D$10 & "'!B:B"))) = $A21) * (INDIRECT("'" & D$10 & "'!B2:B" & COUNTA(INDIRECT("'" & D$10 & "'!B:B"))) <> INDIRECT("'" & D$10 & "'!B1:B" & COUNTA(INDIRECT("'" & D$10 & "'!B:B")) - 1)) ) -> 0 | E21: =SUMPRODUCT( (INDIRECT("'" & E$10 & "'!B2:B" & COUNTA(INDIRECT("'" & E$10 & "'!B:B"))) = $A21) * (INDIRECT("'" & E$10 & "'!B2:B" & COUNTA(INDIRECT("'" & E$10 & "'!B:B"))) <> INDIRECT("'" & E$10 & "'!B1:B" & COUNTA(INDIRECT("'" & E$10 & "'!B:B")) - 1)) ) -> 0 | F21: =SUMPRODUCT( (INDIRECT("'" & F$10 & "'!B2:B" & COUNTA(INDIRECT("'" & F$10 & "'!B:B"))) = $A21) * (INDIRECT("'" & F$10 & "'!B2:B" & COUNTA(INDIRECT("'" & F$10 & "'!B:B"))) <> INDIRECT("'" & F$10 & "'!B1:B" & COUNTA(INDIRECT("'" & F$10 & "'!B:B")) - 1)) ) -> 0 | G21: =SUMPRODUCT( (INDIRECT("'" & G$10 & "'!B2:B" & COUNTA(INDIRECT("'" & G$10 & "'!B:B"))) = $A21) * (INDIRECT("'" & G$10 & "'!B2:B" & COUNTA(INDIRECT("'" & G$10 & "'!B:B"))) <> INDIRECT("'" & G$10 & "'!B1:B" & COUNTA(INDIRECT("'" & G$10 & "'!B:B")) - 1)) ) -> 0 | H21: =SUMPRODUCT( (INDIRECT("'" & H$10 & "'!B2:B" & COUNTA(INDIRECT("'" & H$10 & "'!B:B"))) = $A21) * (INDIRECT("'" & H$10 & "'!B2:B" & COUNTA(INDIRECT("'" & H$10 & "'!B:B"))) <> INDIRECT("'" & H$10 & "'!B1:B" & COUNTA(INDIRECT("'" & H$10 & "'!B:B")) - 1)) ) -> 0 | I21: =SUMPRODUCT( (INDIRECT("'" & I$10 & "'!B2:B" & COUNTA(INDIRECT("'" & I$10 & "'!B:B"))) = $A21) * (INDIRECT("'" & I$10 & "'!B2:B" & COUNTA(INDIRECT("'" & I$10 & "'!B:B"))) <> INDIRECT("'" & I$10 & "'!B1:B" & COUNTA(INDIRECT("'" & I$10 & "'!B:B")) - 1)) ) -> 0 | J21: =SUMPRODUCT( (INDIRECT("'" & J$10 & "'!B2:B" & COUNTA(INDIRECT("'" & J$10 & "'!B:B"))) = $A21) * (INDIRECT("'" & J$10 & "'!B2:B" & COUNTA(INDIRECT("'" & J$10 & "'!B:B"))) <> INDIRECT("'" & J$10 & "'!B1:B" & COUNTA(INDIRECT("'" & J$10 & "'!B:B")) - 1)) ) -> 0 | ... AU21: =SUMPRODUCT( (INDIRECT("'" & AU$10 & "'!B2:B" & COUNTA(INDIRECT("'" & AU$10 & "'!B:B"))) = $A21) * (INDIRECT("'" & AU$10 & "'!B2:B" & COUNTA(INDIRECT("'" & AU$10 & "'!B:B"))) <> INDIRECT("'" & AU$10 & "'!B1:B" & COUNTA(INDIRECT("'" & AU$10 & "'!B:B")) - 1)) ) -> 0
A22: Data collected and structured by dphdmn and vovker, also special thanks to daanbe and ben1996123 for huge help with this project
A23: Slidysim | B23: Open Slidysim Leaderboard | G23: LB Archive | J23: Discord Server | M23: Slidysim Sheet | P23: 6x6 - 10x10 LB | R23: Slidysim Cool Solves Sheet | Y23: [2020 - 2021] Old Kinch | AD23: [2021 - 2023] Old Rankings | AI23: [2019 - 2024] NxM Matrix | AN23: [2018 - 2021] NxN WRs Archive | AS23: Replay Links Fix

Sheet 3x3 ao5
A1: Date | B1: Name | C1: Time | D1: Movecount | E1: TPS | F1: Control | G1: Style | H1: Solve Data | I1: Video
A2: 18.11.2025 | B2: vovker | C2: 0.337 | D2: 13.666 | E2: 41.992 | F2: Tablet | G2: Fringe | H2: In replay | I2: ???
A3: 07.02.2025 | B3: vovker | C3: 0.349 | D3: 14.666 | E3: 40.657 | F3: Mouse | G3: Fringe | H3: In replay | I3: https://youtu.be/gnnoDn-Om3k
A4: 22.05.2024 | B4: dphdmn | C4: 0.394 | D4: 16 | E4: 38.773 | F4: Tablet | G4: Fringe | H4: In replay | I4: https://www.youtube.com/watch?v=XePxX13zehU
A5: 03.06.2022 | B5: vovker | C5: 0.4 | D5: 13.333 | E5: 33.345 | F5: Mouse | G5: Fringe | H5: https://pastebin.com/raw/AcZPvH8z | I5: ???
A6: 14.06.2021 | B6: dphdmn | C6: 0.437 | D6: 15.333 | E6: 35.549 | F6: Tablet | G6: Fringe | H6: https://pastebin.com/raw/ELSMppSU | I6: https://www.youtube.com/watch?v=8zPkQz2W62w
A7: 14.11.2020 | B7: vovker | C7: 0.503 | D7: 16.333 | E7: 32.404 | F7: Mouse | G7: Fringe | H7: https://pastebin.com/raw/v0DcVmxJ | I7: ???
A8: 25.09.2020 | B8: vovker | C8: 0.527 | D8: 15.666 | E8: 29.155 | F8: Mouse | G8: Fringe | H8: 2.400 0.423 0.415 0.511 0.647 | I8: ???
A9: 25.03.2020 | B9: Dawidluna | C9: 0.568 | D9: 15 | E9: 26.973 | F9: Mouse | G9: Fringe | H9: https://pastebin.com/raw/tU9s4jUn | I9: ???
A10: 10.03.2019 | B10: gottagitgud | C10: 0.71 | D10: 13.333 | E10: 18.809 | F10: Keyboard | G10: Fringe | H10: https://www.reddit.com/r/speedsliding/comments/b9618t/8_puzzle_0710_average_of_5/ | I10: ???
A11: 02.01.2016 | B11: ben1996123 | C11: 0.807 | D11: 15.666 | E11: 19.517 | F11: Keyboard | G11: Fringe | H11: (1.843), (0.694), 0.780, 0.744, 0.898 | I11: ???

Sheet 3x3 ao12
A1: Date | B1: Name | C1: Time | D1: Movecount | E1: TPS | F1: Control | G1: Style | H1: Solve Data | I1: Video
A2: 21.02.2025 | B2: dphdmn | C2: 0.505 | D2: 20.7 | E2: 40.787 | F2: Tablet | G2: Fringe | H2: In replay | I2: https://youtu.be/AdNAXgiu1kk
A3: 01.11.2024 | B3: vovker | C3: 0.566 | D3: 19.3 | E3: 33.935 | F3: Mouse | G3: Fringe | H3: In replay | I3: ???
A4: 01.06.2023 | B4: dphdmn | C4: 0.586 | D4: 21.3 | E4: 35.405 | F4: Tablet | G4: Fringe | H4: https://pastebin.com/raw/vM8yiFmn | I4: https://www.youtube.com/watch?v=8kEwjJTETLI
A5: 10.05.2022 | B5: vovker | C5: 0.605 | D5: 19.1 | E5: 31.787 | F5: Mouse | G5: Fringe | H5: https://pastebin.com/raw/5MnbQ5dh | I5: https://www.youtube.com/watch?v=vHnYGbyfe3Y
A6: 22.04.2022 | B6: vovker | C6: 0.66 | D6: 20.4 | E6: 30.427 | F6: Mouse | G6: Fringe | H6: ??? | I6: ???
A7: 22.08.2021 | B7: vovker | C7: 0.689 | D7: 21.2 | E7: 31.026 | F7: Mouse | G7: Fringe | H7: ??? | I7: ???
A8: 08.04.2021 | B8: dphdmn | C8: 0.717 | D8: 21.9 | E8: 30.788 | F8: Tablet | G8: Fringe | H8: https://pastebin.com/raw/9Ti9sg6Q | I8: https://www.youtube.com/watch?v=-pLG9I5VwPk
A9: 15.11.2020 | B9: dphdmn | C9: 0.736 | D9: 21.3 | E9: 29.884 | F9: Tablet | G9: Fringe | H9: https://pastebin.com/raw/E0ge3D49 | I9: https://www.youtube.com/watch?v=MGmab8CqhoE
A10: 26.09.2020 | B10: dphdmn | C10: 0.777 | D10: 23.5 | E10: 29.839 | F10: Tablet | G10: Fringe | H10: https://imgur.com/05M4YiQ | I10: https://www.youtube.com/watch?v=Jmwogvp0B8c
A11: 01.08.2020 | B11: Dawidluna | C11: 0.794 | D11: 19.5 | E11: 24.367 | F11: Mouse | G11: Fringe | H11: ??? | I11: ???
A12: 07.07.2020 | B12: Dawidluna | C12: 0.894 | D12: 22.3 | E12: 24.943 | F12: Mouse | G12: Fringe | H12: https://pastebin.com/raw/jzS3QWuN | I12: ???
A13: 11.05.2020 | B13: Dawidluna | C13: 0.93 | D13: 21.5 | E13: 23.802 | F13: Mouse | G13: Fringe | H13: ??? | I13: ???
... A22: 16.05.2014 | B22: ben1996123 | C22: 1.274 | D22: 20.9 | E22: 16.454 | F22: Keyboard | G22: Fringe | H22: ??? | I22: https://www.youtube.com/watch?v=6hBdXG2ud_Q

Sheet 3x3 ao50
A1: Date | B1: Name | C1: Time | D1: Movecount | E1: TPS | F1: Control | G1: Style | H1: Solve Data | I1: Video
A2: 09.06.2025 | B2: dphdmn | C2: 0.65 | D2: 23.833 | E2: 37.563 | F2: Tablet | G2: Fringe | H2: In replay | I2: https://youtu.be/wRpE-NXbUqQ
A3: 06.04.2025 | B3: dphdmn | C3: 0.722 | D3: 25.166 | E3: 36.027 | F3: Tablet | G3: Fringe | H3: In replay | I3: https://youtu.be/oKS8Cxz-Dfw
A4: 13.03.2025 | B4: dphdmn | C4: 0.741 | D4: 26.354 | E4: 36.466 | F4: Tablet | G4: Fringe | H4: In replay | I4: https://youtu.be/4E_0ttmC6XM
A5: 01.02.2025 | B5: vovker | C5: 0.749 | D5: 23.854 | E5: 33.19 | F5: Mouse | G5: Fringe | H5: In replay | I5: ???
A6: 13.01.2025 | B6: vovker | C6: 0.754 | D6: 23.937 | E6: 32.615 | F6: Mouse | G6: Fringe | H6: https://pastebin.com/raw/QJjzXVTY | I6: ???
A7: 29.10.2024 | B7: vovker | C7: 0.76 | D7: 23.395 | E7: 31.448 | F7: Mouse | G7: Fringe | H7: ??? | I7: ???
A8: 16.08.2024 | B8: vovker | C8: 0.773 | D8: 22.5 | E8: 29.649 | F8: Mouse | G8: Fringe | H8: ??? | I8: ???
A9: 22.05.2024 | B9: dphdmn | C9: 0.801 | D9: 24.708 | E9: 32.366 | F9: Tablet | G9: Fringe | H9: https://pastebin.com/raw/TWTeVUED | I9: https://youtu.be/DSDqLjGPRzU?t=373
A10: 13.11.2023 | B10: dphdmn | C10: 0.805 | D10: 23.604 | E10: 31.104 | F10: Tablet | G10: Fringe | H10: https://pastebin.com/raw/VSJw7A1K | I10: https://youtu.be/Kbc1zEH-zPQ?t=558
A11: 21.08.2022 | B11: dphdmn | C11: 0.823 | D11: 24.916 | E11: 31.433 | F11: Tablet | G11: Fringe | H11: https://pastebin.com/raw/yrWKW6XJ | I11: https://youtu.be/PWf96EPdOLw
A12: 10.05.2022 | B12: vovker | C12: 0.846 | D12: 24.062 | E12: 30.238 | F12: Mouse | G12: Fringe | H12: ??? | I12: ???
A13: 19.04.2022 | B13: vovker | C13: 0.857 | D13: 22.854 | E13: 27.132 | F13: Mouse | G13: Fringe | H13: ??? | I13: ???
... A20: 12.08.2020 | B20: Dawidluna | C20: 1.015 | D20: 24.854 | E20: 25.276 | F20: Mouse | G20: Fringe | H20: ??? | I20: ???
A21: 02.08.2020 | B21: Dawidluna | C21: 1.06 | D21: ??? | E21: ??? | F21: Mouse | G21: Fringe | H21: ??? | I21: ???
A22: 25.03.2020 | B22: Dawidluna | C22: 1.102 | D22: 24.541 | E22: 22.813 | F22: Mouse | G22: Fringe | H22: https://pastebin.com/raw/NbZKR191 | I22: ???
A23: 31.10.2019 | B23: Dawidluna | C23: 1.266 | D23: 27.583 | E23: 22.122 | F23: Mouse | G23: Fringe | H23: ??? | I23: https://www.youtube.com/watch?v=90snF_CyJ0Q
A24: 05.04.2019 | B24: gottagitgud | C24: 1.318 | D24: 23.104 | E24: 17.776 | F24: Keyboard | G24: Fringe | H24: ??? | I24: ???
A25: 06.02.2019 | B25: ben1996123 | C25: 1.336 | D25: 23.27 | E25: 17.676 | F25: Keyboard | G25: Fringe | H25: ??? | I25: https://www.youtube.com/watch?v=BbRYrTdNBAs&t=5s
A26: 17.10.2015 | B26: ben1996123 | C26: 1.349 | D26: ??? | E26: ??? | F26: Keyboard | G26: Fringe | H26: ??? | I26: ???

Sheet 3x3 ao100
A1: Date | B1: Name | C1: Time | D1: Movecount | E1: TPS | F1: Control | G1: Style | H1: Solve Data | I1: Video
A2: 05.04.2026 | B2: dphdmn | C2: 0.736 | D2: 26.153 | E2: 37.017 | F2: Tablet | G2: Fringe | H2: In replay | I2: https://youtu.be/9XrEJvCS0MY
A3: 04.03.2026 | B3: dphdmn | C3: 0.745 | D3: 25.877 | E3: 37.113 | F3: Tablet | G3: Fringe | H3: In replay | I3: ???
A4: 06.04.2025 | B4: dphdmn | C4: 0.746 | D4: 25.622 | E4: 35.809 | F4: Tablet | G4: Fringe | H4: In replay | I4: https://youtu.be/oKS8Cxz-Dfw
A5: 22.03.2025 | B5: dphdmn | C5: 0.793 | D5: 25.918 | E5: 34.403 | F5: Tablet | G5: Fringe | H5: In replay | I5: https://youtu.be/OvLDB9tA5uY
A6: 10.01.2025 | B6: vovker | C6: 0.798 | D6: 24.163 | E6: 31.405 | F6: Mouse | G6: Fringe | H6: In replay | I6: https://youtu.be/vBow-Nhdwto
A7: 05.11.2024 | B7: vovker | C7: 0.835 | D7: 24.581 | E7: 30.792 | F7: Mouse | G7: Fringe | H7: ??? | I7: ???
A8: 01.11.2024 | B8: vovker | C8: 0.838 | D8: 24.53 | E8: 30.504 | F8: Mouse | G8: Fringe | H8: ??? | I8: ???
A9: 01.06.2023 | B9: dphdmn | C9: 0.845 | D9: 26.346 | E9: 32.592 | F9: Tablet | G9: Fringe | H9: https://pastebin.com/raw/dwadcnik | I9: https://youtu.be/HMcN5rO1DJg
A10: 22.01.2023 | B10: dphdmn | C10: 0.889 | D10: 26.938 | E10: 32.007 | F10: Tablet | G10: Fringe | H10: https://pastebin.com/raw/dPBHi64T | I10: https://www.youtube.com/watch?v=qzBWPeZ7LDY
A11: 07.05.2022 | B11: vovker | C11: 0.915 | D11: 24.54 | E11: 27.782 | F11: Mouse | G11: Fringe | H11: ??? | I11: ???
A12: 22.04.2022 | B12: vovker | C12: 0.952 | D12: 25.326 | E12: 27.759 | F12: Mouse | G12: Fringe | H12: ??? | I12: ???
A13: 14.01.2022 | B13: Dawidluna | C13: 0.961 | D13: 26.489 | E13: 28.239 | F13: Mouse | G13: Fringe | H13: ??? | I13: ???
... A18: 01.08.2020 | B18: Dawidluna | C18: 1.131 | D18: 26.091 | E18: 23.67 | F18: Mouse | G18: Fringe | H18: ??? | I18: ???
A19: <01.08.2020 | B19: Dawidluna | C19: 1.195 | D19: ??? | E19: ??? | F19: Mouse | G19: Fringe | H19: ??? | I19: ???
A20: 21.07.2020 | B20: Dawidluna | C20: 1.199 | D20: ??? | E20: ??? | F20: Mouse | G20: Fringe | H20: ??? | I20: ???
A21: 25.03.2020 | B21: Dawidluna | C21: 1.238 | D21: 27.051 | E21: 22.303 | F21: Mouse | G21: Fringe | H21: https://pastebin.com/raw/DtxwNa1b | I21: ???
A22: 31.10.2019 | B22: Dawidluna | C22: 1.328 | D22: 28.51 | E22: 21.917 | F22: Mouse | G22: Fringe | H22: ??? | I22: https://youtu.be/90snF_CyJ0Q
A23: 11.07.2019 | B23: gottagitgud | C23: 1.387 | D23: 23 | E23: 16.799 | F23: Keyboard | G23: Fringe | H23: ??? | I23: ???
A24: 17.10.2015 | B24: ben1996123 | C24: 1.391 | D24: 23.622 | E24: 17.191 | F24: Keyboard | G24: Fringe | H24: https://pastebin.com/raw/kVJXJ5yY | I24: ???
A25: 10.10.2015 | B25: ben1996123 | C25: 1.432 | D25: 24.183 | E25: 17.115 | F25: Keyboard | G25: Fringe | H25: https://pastebin.com/raw/bX7gRTjQ | I25: https://www.youtube.com/watch?v=vq6MO2chLRc&t=201s

Sheet 3x3 x10
A1: Date | B1: Name | C1: Time | D1: Movecount | E1: TPS | F1: Control | G1: Style | H1: Solve Data | I1: Video
A2: 28.06.2025 | B2: dphdmn | C2: 9.953 | D2: 241 | E2: 24.213 | F2: Tablet | G2: Fringe | H2: In replay | I2: https://youtu.be/Vgs0Yb5JH6Y
A3: 25.02.2025 | B3: dphdmn | C3: 9.961 | D3: 221 | E3: 22.187 | F3: Tablet | G3: Fringe | H3: In replay | I3: https://youtu.be/qF1nbzR5EU8
A4: 05.02.2025 | B4: vovker | C4: 10.061 | D4: 222 | E4: 22.065 | F4: Mouse | G4: Fringe | H4: In replay | I4: https://youtu.be/N6op9neeUDc
A5: 01.10.2024 | B5: vovker | C5: 10.31 | D5: 199 | E5: 19.301 | F5: Mouse | G5: Fringe | H5: In vid desc | I5: https://www.youtube.com/watch?v=Otvxaz2Wl_I
A6: 01.10.2024 | B6: dphdmn | C6: 10.973 | D6: 217 | E6: 19.776 | F6: Tablet | G6: Fringe | H6: In vid comment | I6: https://www.youtube.com/watch?v=2JLJoV1cKdo
A7: 12.09.2024 | B7: vovker | C7: 10.999 | D7: 224 | E7: 20.365 | F7: Mouse | G7: Fringe | H7: https://pastebin.com/raw/JPBk4aKn | I7: ???
A8: 26.08.2022 | B8: dphdmn | C8: 11.123 | D8: 248 | E8: 22.296 | F8: Tablet | G8: Fringe | H8: https://pastebin.com/raw/Ax687sdv | I8: https://www.youtube.com/watch?v=7_IkU9lyHb4
A9: 13.06.2022 | B9: vovker | C9: 11.415 | D9: 214 | E9: 18.747 | F9: Mouse | G9: Fringe | H9: https://pastebin.com/raw/xRHBSqCnn | I9: https://www.youtube.com/watch?v=oUbQpN7hf4w
A10: 24.06.2021 | B10: dphdmn | C10: 11.903 | D10: 240 | E10: 20.162 | F10: Tablet | G10: Fringe | H10: https://pastebin.com/raw/TyeGNvJ6 | I10: https://www.youtube.com/watch?v=Lh6y2Nsktwc
A11: 23.06.2021 | B11: dphdmn | C11: 12.771 | D11: 229 | E11: 17.931 | F11: Tablet | G11: Fringe | H11: ??? | I11: ???
A12: 07.04.2021 | B12: dphdmn | C12: 12.782 | D12: 237 | E12: 18.541 | F12: Tablet | G12: Fringe | H12: https://pastebin.com/raw/tTextr5A | I12: https://www.youtube.com/watch?v=D9dW4dzKabc
A13: 11.02.2021 | B13: vovker | C13: 13.103 | D13: 231 | E13: 17.629 | F13: Mouse | G13: Fringe | H13: https://pastebin.com/raw/x1sYk8Vk | I13: ???
... A22: 01.07.2015 | B22: soup | C22: 19.072 | D22: 273 | E22: 14.314 | F22: Mouse | G22: LBL | H22: ??? | I22: ???

Sheet 3x3 x42
A1: Date | B1: Name | C1: Time | D1: Movecount | E1: TPS | F1: Control | G1: Style | H1: Solve Data | I1: Video
A2: 02.08.2025 | B2: dphdmn | C2: 49.962 | D2: 1202 | E2: 24.058 | F2: Tablet | G2: Fringe | H2: In replay | I2: https://youtu.be/BbMYZRThyxo
A3: 02.08.2025 | B3: dphdmn | C3: 50.426 | D3: 1156 | E3: 22.924 | F3: Tablet | G3: Fringe | H3: In replay | I3: ???
A4: 01.06.2025 | B4: dphdmn | C4: 50.692 | D4: 1101 | E4: 21.719 | F4: Tablet | G4: Fringe | H4: In replay | I4: https://www.youtube.com/watch?v=PDyn_fLcT70
A5: 06.02.2025 | B5: dphdmn | C5: 51.261 | D5: 1031 | E5: 20.112 | F5: Tablet | G5: Fringe | H5: In replay | I5: https://youtu.be/I_12rOWXcgg
A6: 10.01.2025 | B6: vovker | C6: 53.423 | D6: 1078 | E6: 20.179 | F6: Mouse | G6: Fringe | H6: In replay | I6: https://www.youtube.com/watch?v=e33CrqUNTAM
A7: 10.01.2025 | B7: vovker | C7: 53.635 | D7: 1096 | E7: 20.434 | F7: Mouse | G7: Fringe | H7: ??? | I7: ???
A8: 10.01.2025 | B8: vovker | C8: 54.48 | D8: 1054 | E8: 19.346 | F8: Mouse | G8: Fringe | H8: ??? | I8: ???
A9: 02.01.2025 | B9: vovker | C9: 55.583 | D9: 1133 | E9: 20.383 | F9: Mouse | G9: Fringe | H9: ??? | I9: ???
A10: 02.01.2025 | B10: vovker | C10: 56.068 | D10: 1057 | E10: 18.852 | F10: Mouse | G10: Fringe | H10: ??? | I10: ???
A11: 08.12.2024 | B11: vovker | C11: 56.09 | D11: 1078 | E11: 19.219 | F11: Mouse | G11: Fringe | H11: ??? | I11: https://youtu.be/B1J2H9d36wo
A12: 11.10.2024 | B12: vovker | C12: 56.326 | D12: 1065 | E12: 18.907 | F12: Mouse | G12: Fringe | H12: In vid desc | I12: https://www.youtube.com/watch?v=TCZok1Lt4eo
A13: 19.04.2023 | B13: dphdmn | C13: 56.759 | D13: 1139 | E13: 20.067 | F13: Tablet | G13: Fringe | H13: https://pastebin.com/raw/EUnZzw4A | I13: https://youtu.be/RB6jo49Wbsc
... A32: 04.06.2015 | B32: ben1996123 | C32: 97.095 | D32: 1127 | E32: 11.607 | F32: Keyboard | G32: Fringe | H32: ??? | I32: ???

Sheet 4x4 single
A1: Date | B1: Name | C1: Time | D1: Movecount | E1: TPS | F1: Control | G1: Style | H1: Scramble | I1: Solution | J1: Video
A2: 20.05.2025 | B2: dphdmn | C2: 0.909 | D2: 26 | E2: 28.602 | F2: Tablet | G2: Fringe | H2: 7 1 0 3/5 9 2 8/13 6 11 4/10 14 15 12 | I2: R2ULDLULU2R3D3L3UR2U2L2 | J2: https://youtu.be/aNzNFn8fQMw
A3: 08.09.2024 | B3: dphdmn | C3: 0.946 | D3: 33 | E3: 34.883 | F3: Tablet | G3: Fringe | H3: 10 0 5 2/6 4 1 3/9 14 8 12/13 7 11 15 | I3: LUR2DL3UR3DL3U3R2D2LU2LD2RU2L | J3: https://www.youtube.com/watch?v=RRjOcl3efDU
A4: 31.10.2020 | B4: ben1996123 | C4: 0.953 | D4: 23 | E4: =D4/C4 -> 24.134313 | F4: Tablet | G4: Fringe | H4: 1 2 4 8/11 7 0 3/6 14 10 12/5 9 13 15 | I4: LDRUR2U2L2DRDRU2L2DRUL2 | J4: https://www.youtube.com/watch?v=gclz6T9Z85Q
A5: 24.10.2020 | B5: vovker | C5: 1.184 | D5: 28 | E5: =D5/C5 -> 23.648649 | F5: Mouse | G5: Fringe | H5: 5 1 4 8/3 6 7 0/13 15 2 10/14 9 11 12 | I5: RURDRDLUL2DR2U3LDLUR3DL2UL | J5: https://youtu.be/e_00dkcP41A
A6: 29.09.2020 | B6: dphdmn | C6: 1.342 | D6: 34 | E6: =D6/C6 -> 25.33532 | F6: Tablet | G6: Fringe | H6: 3 10 2 4/1 14 7 0/9 12 5 8/13 11 15 6 | I6: RURDLDR2UL2DRUL2U2RDLDRU2RD2L2URUL | J6: https://youtu.be/pZ9Qdb4kHMI
A7: 05.09.2016 | B7: ben1996123 | C7: 1.442 | D7: 26 | E7: =D7/C7 -> 18.030513 | F7: Keyboard | G7: Fringe | H7: 1 2 3 4/12 13 11 7/5 10 6 8/14 9 15 0 | I7: R2D2RUL2DRU2LDRURDL2DLURUL | J7: https://www.youtube.com/watch?v=ZITqHOGIdX4
A8: 13.11.2014 | B8: ben1996123 | C8: 1.788 | D8: 28 | E8: =D8/C8 -> 15.659955 | F8: Keyboard | G8: Fringe | H8: 1 3 9 4/8 14 2 10/5 15 6 11/13 0 12 7 | I8: D2LDRUL2U2R2D2RUL2DRUL2DRULU | J8: https://www.youtube.com/watch?v=mw9vowCC9IU
A9: 17.07.2014 | B9: ben1996123 | C9: 2 | D9: 33 | E9: =D9/C9 -> 16.5 | F9: Keyboard | G9: Fringe | H9: 6 7 1 4/14 13 2 8/5 3 10 12/11 9 0 15 | I9: DRDDLUURDRDLLURULDRRULURDLLURDLUL | J9: https://www.youtube.com/watch?v=Wwqz7kvIl3Q
A10: 26.01.2014 | B10: ben1996123 | C10: 2.208 | D10: 38 | E10: =D10/C10 -> 17.210145 | F10: Keyboard | G10: Fringe | H10: 8 3 4 15/14 2 6 0/5 1 9 7/13 12 10 11 | I10: DRRUULDDRURDLLURRULLDRULLDRUURDLULDRUL | J10: https://www.youtube.com/watch?v=d936xjpIleA
A11: 21.10.2013 | B11: ben1996123 | C11: 2.568 | D11: 37 | E11: 14.408 | F11: Keyboard | G11: Fringe | H11: 1 0 2 4/9 5 7 14/10 11 3 6/12 13 15 8 | I11: ULURDDLUURRULDRDLLULDRULURDRDLLURRULL | J11: not recorded
A12: 10.10.2013 | B12: ben1996123 | C12: 2.791 | D12: 44 | E12: =D12/C12 -> 15.764959 | F12: Keyboard | G12: Fringe | H12: 1 8 0 15/5 4 6 2/9 3 12 10/13 7 11 14 | I12: RUULDLDRRULLDRRULURULDRDLULURRDLURDLLURDRULL | J12: https://www.youtube.com/watch?v=QBcoSeD5lL8
A13: 02.10.2013 | B13: ben1996123 | C13: 3.351 | D13: 43 | E13: =D13/C13 -> 12.83199 | F13: Keyboard | G13: Fringe | H13: 7 6 10 0/3 4 9 11/1 2 5 8/13 14 15 12 | I13: RRULDRRUULDDRUULDRULLDLDRRUURDLULDLURDRULLU | J13: https://www.youtube.com/watch?v=Oq6Fn-tQ-JE
A14: 26.09.2013 | B14: ben1996123 | C14: 3.519 | D14: 50 | E14: =D14/C14 -> 14.208582 | F14: Keyboard | G14: Fringe | H14: ... | I14: ... | J14: https://www.youtube.com/watch?v=dUZckVJVRbg

Sheet 4x4 ao5
A1: Date | B1: Name | C1: Time | D1: Movecount | E1: TPS | F1: Control | G1: Style | H1: Solve Data | I1: Video
A2: 02.09.2025 | B2: dphdmn | C2: 1.794 | D2: 58 | E2: 30.992 | F2: Tablet | G2: Fringe | H2: In replay | I2: https://youtu.be/X8rsJu13GSA
A3: 25.05.2025 | B3: vovker | C3: 1.829 | D3: 57.333 | E3: 29.814 | F3: Mouse | G3: Fringe | H3: In replay | I3: https://www.youtube.com/watch?v=GvtJv-2sSn4
A4: 03.03.2025 | B4: dphdmn | C4: 1.916 | D4: 61.333 | E4: 31.709 | F4: Tablet | G4: Fringe | H4: In replay | I4: https://youtu.be/YblLg_oqMOg
A5: 07.02.2025 | B5: vovker | C5: 1.95 | D5: 51.666 | E5: 24.28 | F5: Mouse | G5: Fringe | H5: In replay | I5: https://www.youtube.com/watch?v=l7LG_l0mgVE
A6: 09.09.2024 | B6: vovker | C6: 1.995 | D6: 54.666 | E6: 27.436 | F6: Mouse | G6: Fringe | H6: In vid desc | I6: https://www.youtube.com/watch?v=F-jxLmRzpiE
A7: 18.05.2024 | B7: dphdmn | C7: 2.049 | D7: 62 | E7: 29.747 | F7: Tablet | G7: Fringe | H7: In replay | I7: https://youtu.be/6lITiyo4yXc
A8: 18.02.2023 | B8: dphdmn | C8: 2.114 | D8: 62 | E8: 27.286 | F8: Tablet | G8: Fringe | H8: https://pastebin.com/raw/yPguXYRu | I8: https://www.youtube.com/watch?v=FXyGXFs9Kjo
A9: 14.08.2022 | B9: dphdmn | C9: 2.132 | D9: 61.333 | E9: 28.414 | F9: Tablet | G9: Fringe | H9: https://pastebin.com/raw/AptS6srV | I9: https://youtu.be/UUYhJj4QGh8?t=34
A10: 13.02.2022 | B10: Dawidluna | C10: 2.273 | D10: 57 | E10: 25.854 | F10: Mouse | G10: Fringe | H10: https://pastebin.com/raw/8q6bq4XZ | I10: https://www.youtube.com/watch?v=tAhJcBPqZF0
A11: 26.01.2022 | B11: Dawidluna | C11: 2.323 | D11: 61.666 | E11: 26.763 | F11: Mouse | G11: Fringe | H11: https://pastebin.com/raw/asPrXny0 | I11: https://www.youtube.com/watch?v=7BaZOVwQhYU
A12: 11.12.2021 | B12: Dawidluna | C12: 2.382 | D12: 65.666 | E12: 25.611 | F12: Mouse | G12: Fringe | H12: ??? | I12: ???
A13: 31.05.2021 | B13: dphdmn | C13: 2.39 | D13: 66.666 | E13: 27.886 | F13: Tablet | G13: Fringe | H13: https://pastebin.com/raw/VmUQ6RZB | I13: https://www.youtube.com/watch?v=F0y3kwhb1tI
... A21: 21.07.2020 | B21: Dawidluna | C21: 2.764 | D21: 65.333 | E21: 22.947 | F21: Mouse | G21: Fringe | H21: 2.676 (missing), 2.719, 2.898, (2.666), (3.743) | I21: https://www.youtube.com/watch?v=oRp1jxWsLLc
A22: 19.07.2020 | B22: Dawidluna | C22: 3.127 | D22: ??? | E22: ??? | F22: Mouse | G22: Fringe | H22: ??? | I22: ???
A23: 08.07.2020 | B23: Dawidluna | C23: 3.145 | D23: 65.333 | E23: 21.227 | F23: Mouse | G23: Fringe | H23: ??? | I23: https://www.youtube.com/watch?v=VmvJABsuZOo
A24: 05.05.2020 | B24: ben1996123 | C24: 3.172 | D24: 51.666 | E24: 15.336 | F24: Keyboard | G24: Fringe | H24: (2.456) (35) 14.250 5 1 12 2/9 10 6 4/13 14 3 8/7 15 0 11 R2D3L3URU2RD3LULURURD2LURUL2DRUL 05 May 2016, 23:34 3.346 53 15.839 12 15 3 8/2 5 1 7/4 11 10 6/0 9 13 14 L2DR2DL2UR2DL2URD2RU3LD3LU2RDL2URDLDR2ULURUL2DR2UL2 05 May 2016, 23:35 3.266 52 15.921 15 13 0 11/4 14 1 5/2 8 3 9/10 6 12 7 U2RDRDL2UR2ULDRDL2ULDR2ULURURD2LUL2UR2DL2DRU2R2DL3U 05 May 2016, 23:36 (7.580) (99) (13.060) 8 14 3 15/0 10 12 5/13 7 11 4/9 2 1 6 LU2LD2RU2LD2LDR2U2LDLURD2RURDL3URULUR3DL3DR3UL2DR2ULULDLDRUR2DLULDR2UL2DLU2R2DL2URDLDR2ULULDRUL 05 May 2016, 23:38 2.906 50 (17.205) 10 2 5 4/3 0 1 8/14 9 12 7/15 6 13 11 RDLULUR2DL2URDLDR2UL2URULDR2ULDRDL2ULUR2D2LU2RDL2U 05 May 2016, 23:38 3.172 51.666 15.336 0.191 | I24: ???
A25: 14.04.2015 | B25: ben1996123 | C25: 3.701 | D25: 52 | E25: 13.975 | F25: Keyboard | G25: Fringe | H25: ??? | I25: ???
A26: 10.10.2014 | B26: ben1996123 | C26: 3.891 | D26: 60.333 | E26: 15.139 | F26: Keyboard | G26: Fringe | H26: https://pastebin.com/ZTZV7Lhq | I26: https://www.youtube.com/watch?v=_qCzKWDXg9k
A27: <9.06.2014 | B27: ben1996123 | C27: 3.951 | D27: ??? | E27: ??? | F27: Keyboard | G27: Fringe | H27: ??? | I27: ???
A28: 15.12.2013 | B28: ben1996123 | C28: 4.319 | D28: 60 | E28: 14.771 | F28: Keyboard | G28: Fringe | H28: 5.127, 3.799, (3.551), (5.128), 4.031 | I28: https://www.youtube.com/watch?v=afhsxwSgTUM
A29: 12.10.2013 | B29: ben1996123 | C29: 4.956 | D29: ??? | E29: ??? | F29: Keyboard | G29: Fringe | H29: (6.671), 4.911, (3.304), 5.399, 4.559 | I29: https://www.youtube.com/watch?v=sGH46jNIyi4

Sheet 4x4 ao12
A1: Date | B1: Name | C1: Time | D1: Movecount | E1: TPS | F1: Control | G1: Style | H1: Solve Data | I1: Video
A2: 14.03.2026 | B2: dphdmn | C2: 2.157 | D2: 66.6 | E2: 30.74 | F2: Tablet | G2: Fringe | H2: In replay | I2: https://youtu.be/R56tnvSorb4
A3: 03.10.2025 | B3: dphdmn | C3: 2.243 | D3: 71 | E3: 31.63 | F3: Tablet | G3: Fringe | H3: In replay | I3: https://youtu.be/twShIWqsjNI
A4: 21.08.2025 | B4: dphdmn | C4: 2.249 | D4: 73.1 | E4: 32.48 | F4: Tablet | G4: Fringe | H4: In replay | I4: https://youtu.be/ACcWHdXRIV8
A5: 10.06.2025 | B5: dphdmn | C5: 2.295 | D5: 72.8 | E5: 31.177 | F5: Tablet | G5: Fringe | H5: In replay | I5: https://youtu.be/tIOTaEGgfL0
A6: 03.04.2025 | B6: dphdmn | C6: 2.301 | D6: 72.1 | E6: 31.296 | F6: Tablet | G6: Fringe | H6: In replay | I6: https://youtu.be/YpRsSiulSnM
A7: 21.03.2025 | B7: dphdmn | C7: 2.356 | D7: 68.8 | E7: 29.072 | F7: Tablet | G7: Fringe | H7: In replay | I7: https://youtu.be/8cV1WE7RzbY?t=194
A8: 11.03.2025 | B8: dphdmn | C8: 2.371 | D8: 71.4 | E8: 31.252 | F8: Tablet | G8: Fringe | H8: In replay | I8: https://youtu.be/yS69K9xcW8o?t=115
A9: 11.03.2025 | B9: dphdmn | C9: 2.427 | D9: 75.1 | E9: 30.709 | F9: Tablet | G9: Fringe | H9: https://raw.githubusercontent.com/dphdmn/mytextfiles/refs/heads/main/slidy/badao12data.txt | I9: https://youtu.be/wWTzXh8bmNE?t=894
A10: 29.10.2024 | B10: vovker | C10: 2.461 | D10: 68.3 | E10: 27.515 | F10: Mouse | G10: Fringe | H10: In replay | I10: ???
A11: 16.09.2024 | B11: vovker | C11: 2.497 | D11: 64.6 | E11: 26.295 | F11: Mouse | G11: Fringe | H11: ??? | I11: ???
A12: 25.01.2023 | B12: dphdmn | C12: 2.584 | D12: 72 | E12: 27.971 | F12: Tablet | G12: Fringe | H12: https://pastebin.com/raw/NsERsutL | I12: https://youtu.be/nqNoX9WQLMw
